Error in atexit._run_exitfuncs:
Traceback (most recent call last):
  File "/usr/local/Cellar/python@3.9/3.9.2_1/Frameworks/Python.framework/Versions/3.9/lib/python3.9/subprocess.py", line 1189, in wait
    return self._wait(timeout=timeout)
  File "/usr/local/Cellar/python@3.9/3.9.2_1/Frameworks/Python.framework/Versions/3.9/lib/python3.9/subprocess.py", line 1919, in _wait
    (pid, sts) = self._try_wait(0)
  File "/usr/local/Cellar/python@3.9/3.9.2_1/Frameworks/Python.framework/Versions/3.9/lib/python3.9/subprocess.py", line 1877, in _try_wait
    (pid, sts) = os.waitpid(self.pid, wait_flags)
KeyboardInterrupt
